Workbook

Sheet サマリー
A1: SageMaker MLOps コスト試算シミュレータ — サマリー
A2: 「入力」シートで前提を変更してください。本サマリーはA/B/Cの内訳と比較を表示します。
A4: リージョン（固定） | B4: =入力!B5
A5: ユーザー数（U） | B5: =入力!B7
A6: 月間推論リクエスト数（合計） | B6: =入力!B53+入力!B54
A7: コンポーネント | B7: A（個人） | C7: B（グループ） | D7: C（共通）
A8: 再学習パイプライン | B8: =詳細_再学習!B14 | C8: =詳細_再学習!C14 | D8: =詳細_再学習!D14
A9: ドリフト監視 | B9: =詳細_監視!B10 | C9: =詳細_監視!C10 | D9: =詳細_監視!D10
A10: 再学習トリガー | B10: =詳細_トリガー!B6 | C10: =詳細_トリガー!C6 | D10: =詳細_トリガー!D6
A11: モデル成果物保管（S3） | B11: =詳細_モデル管理!B7 | C11: =詳細_モデル管理!C7 | D11: =詳細_モデル管理!D7
A12: 推論 | B12: =詳細_推論!B23 | C12: =詳細_推論!C23 | D12: =詳細_推論!D23
A13: 合計 | B13: =SUM(B8:B12) | C13: =SUM(C8:C12) | D13: =SUM(D8:D12)

Sheet コスト発生理由
A1: AWSサービス別：コストが発生する理由（参照リンク付き）
A3: ※本ブックの各コンポーネント（再学習・監視・推論・トリガー・モデル保管）で、どのAWSサービスに何の費用が発生するかを整理しています。
A5: コンポーネント | B5: AWSサービス | C5: 課金単位（支配要因） | D5: なぜコストが発生するか（理由） | E5: 本ブックで参照する入力セル例 | F5: 公式リンク
A6: 再学習（前処理/評価） | B6: SageMaker Processing | C6: インスタンス時間（USD/時間 × 実行時間 × 台数） | D6: 前処理・評価はCPU/メモリ/I/Oを消費するため。ECRイメージロードなどの固定オーバーヘッドも時間に含まれる。 | E6: 入力!B19〜B23（時間）, 入力!B27（インスタンス） | F6: https://aws.amazon.com/sagemaker/ai/pricing/
A7: 再学習（学習） | B7: SageMaker Training | C7: インスタンス時間（USD/時間 × 実行時間 × 台数） | D7: モデル学習は計算資源を集中的に使用するため。分散学習では台数増によりコスト増。 | E7: 入力!B20（学習時間）, 入力!B28（インスタンス） | F7: https://aws.amazon.com/sagemaker/ai/pricing/
A8: 評価ゲート | B8: SageMaker Processing | C8: インスタンス時間 | D8: 精度指標算出・閾値判定を実行するため、計算ジョブとしてコストが発生する。 | E8: 入力!B21（評価時間） | F8: https://aws.amazon.com/sagemaker/ai/pricing/
A9: ドリフト監視 | B9: SageMaker Model Monitor（または自作Processing） | C9: 監視ジョブのインスタンス時間（＋データ処理量） | D9: 入力分布や予測品質の集計・統計判定を定期実行するため。監視頻度×対象数に比例して増える。 | E9: 入力!B35〜B38（監視設定）, 入力!B27（監視インスタンス） | F9: https://aws.amazon.com/sagemaker/ai/pricing/
A10: 推論（Serverless） | B10: SageMaker Serverless Inference | C10: 実行時間（USD/秒）＋データ処理量（USD/GB） | D10: 推論実行中のみ課金。入力/出力データ量にも従量課金。機能制約により監視は別設計が必要な場合あり。 | E10: 入力!B59〜B64（Serverless） | F10: https://docs.aws.amazon.com/sagemaker/latest/dg/serverless-endpoints.html
A11: 推論（Real-time） | B11: SageMaker Real-time Endpoint | C11: 常時稼働インスタンス時間（USD/時間 × 730h × 台数） | D11: エンドポイントは常時起動のため、リクエストが少なくても固定費が発生。SLOが厳しい場合に適する。 | E11: 入力!B67〜B70（Real-time） | F11: https://aws.amazon.com/sagemaker/ai/pricing/
A12: 推論（Batch） | B12: SageMaker Batch Transform（またはBatch推論） | C12: ジョブ実行中のインスタンス時間 | D12: 指定時間帯にまとめて推論を実行するため、実行時間に応じて課金。常時エンドポイント不要。 | E12: 入力!B73〜B75（Batch） | F12: https://aws.amazon.com/sagemaker/ai/pricing/
A13: 再学習トリガー | B13: Amazon EventBridge | C13: 呼び出し回数（100万回あたり） | D13: スケジュール/イベントでパイプラインを起動するたびに課金。一般に小さいが、実行回数に比例して増える。 | E13: 入力!B46〜B47（EventBridge） | F13: https://aws.amazon.com/eventbridge/pricing/
A14: モデル成果物保管 | B14: Amazon S3 | C14: 容量（GB-month） | D14: モデル成果物・評価結果などのファイル保管により容量課金。モデル数×サイズ×保持世代で増加。 | E14: 入力!B41〜B43（S3） | F14: https://aws.amazon.com/s3/pricing/

Sheet 単価
A1: インスタンスタイプ | B1: 単価（USD/時間） | C1: 備考
A2: ml.m5.large | B2: 0.115 | C2: 汎用（バランス）。m5.xlargeの半分の規模。
A3: ml.m5.xlarge | B3: 0.23 | C3: 汎用（バランス）。CPU前提の学習/前処理の基準。
A4: ml.m5.2xlarge | B4: 0.46 | C4: 汎用。xlargeの約2倍リソース。
A5: ml.m5.4xlarge | B5: 0.922 | C5: 汎用。重めの監視ジョブ等の例。
A6: ml.c5.large | B6: 0.102 | C6: 計算最適化。CPUバウンド推論に向く。
A7: ml.c5.xlarge | B7: 0.204 | C7: 計算最適化。リアルタイム推論の基準例。
A8: ml.c5.2xlarge | B8: 0.408 | C8: 計算最適化。約2倍リソース。
A9: ml.r5.xlarge | B9: 0.252 | C9: メモリ最適化。メモリ支配の処理に向く。
A10: ml.r5.2xlarge | B10: 0.504 | C10: メモリ最適化。約2倍リソース。
A13: Serverlessメモリ（GB） | B13: 単価（USD/秒） | C13: 備考
A14: 1 | B14: 2e-05 | C14: 仮置き。リージョン/プランに合わせて調整してください。
A15: 2 | B15: 4e-05 | C15: 2GBの代表例。必要に応じて調整してください。
A16: 4 | B16: 8e-05 | C16: 仮置き（線形スケール仮定）。
A17: 6 | B17: 0.00012 | C17: 仮置き（線形スケール仮定）。

Sheet 入力
A1: SageMaker MLOps コスト試算シミュレータ（us-east-1）— 入力
A2: 青色の文字セルは入力（変更可能）です。黒色の文字セルは計算式です。単位は列Cに記載しています。
A4: A. ユーザー数・モデル数（A/B/Cそれぞれ入力）
A5: リージョン（固定） | B5: us-east-1 | C5: text
A6: モデル数（M_A：A 個人モデル数） | B6: =B7 | C6: models | D6: 既定：ユーザー数と同じ（上書き可）
A7: ユーザー数（U） | B7: 100000 | C7: users
A8: グループ数（G）※パターンBで使用 | B8: 200 | C8: groups
A9: モデル数（M_B：B グループモデル数） | B9: =B8 | C9: models | D9: 既定：グループ数と同じ（上書き可）
A10: モデル数（M_C：C 共通モデル数） | B10: 1 | C10: models | D10: 既定：1（上書き可）
A11: B. Retraining Frequency & Job Overheads
A12: 再学習サイクル頻度（月あたり） | B12: 1 | C12: cycles/month
A13: 追加再学習係数（ドリフト/アラート等） | B13: 0.2 | C13: fraction | D13: 0.20 = +20%
A14: 合計再学習サイクル回数（R）（月あたり） | B14: =B12*(1+B13) | C14: cycles/month
A15: ECRイメージロード時間（Processing） | B15: 2 | C15: min/job
A16: ECRイメージロード時間（Training） | B16: 3 | C16: min/job
A18: C. 再学習時間（前処理は共通化、学習のみモデル数で変動）
A19: 前処理時間（t_p）（共通：1サイクルあたり） | B19: 15 | C19: min/cycle
A20: 学習時間（t_t）（モデルあたり：1回の学習） | B20: 30 | C20: min/model/run
A21: 評価＋ゲート判定時間（t_e）（共通：1サイクルあたり） | B21: 10 | C21: min/cycle
A22: Processing分（共通：前処理＋評価、ECR含む） | B22: =(B19+B15)+(B21+B15) | C22: minutes
A23: Training分（モデルあたり：学習、ECR含む） | B23: =B20+B16 | C23: minutes
A24: （参考）1サイクルあたりのProcessing分＋Training分（モデルあたり） | B24: =B22+B23 | C24: minutes
A26: D. インスタンス選定
A27: Processing用インスタンスタイプ（前処理/評価/監視） | B27: ml.m5.xlarge | C27: instance
A28: Training用インスタンスタイプ | B28: ml.m5.xlarge | C28: instance
A29: リアルタイムエンドポイント用インスタンスタイプ | B29: ml.c5.xlarge | C29: instance
A30: バッチ推論用インスタンスタイプ | B30: ml.m5.xlarge | C30: instance
A32: E. ドリフト監視（データ/モデル）
A33: 監視の単位（エンティティ） | B33: PerEndpoint | C33: PerEndpoint/PerModel | D33: Serverless => custom monitoring recommended
A34: エンドポイント数 | B34: 1 | C34: endpoints
A35: 監視実行回数（月） | B35: 30 | C35: runs/month
A36: 監視ジョブ実行時間（オーバーヘッド除外） | B36: 5 | C36: min/run
A37: 監視分（オーバーヘッド込み） | B37: =B36+B15 | C37: min/run
A38: 監視対象数（参考：PerEndpoint時のみ） | B38: =IF(B33="PerEndpoint",B34,"") | C38: entities
A40: F. モデル保管/レジストリ（S3）
A41: モデル成果物サイズ | B41: 20 | C41: MB/model/version
A42: 保持バージョン数 | B42: 6 | C42: versions
A43: S3ストレージ単価 | B43: 0.023 | C43: USD/GB-month | D43: Adjust if using different class/discount
A45: G. 再学習トリガー（EventBridge）
A46: トリガー回数（月） | B46: =B14 | C46: events/month | D46: e.g., daily schedule
...

Sheet ガイド
A1: 使い方 / 注意点（日本語）
A3: 1) 「入力」シートの青文字セルを変更してください（頻度・時間・インスタンス・推論方式など）。 2) 「単価」シートは us-east-1 のオンデマンド単価を入力してください（必要に応じて行を追加）。 3) 「サマリー」で選択パターンの月額合計とA/B/C比較を確認できます。 重要な考え方： - 再学習（Processing/Training）は「インスタンス単価 × 実行時間 × 台数」の合計が支配します。 - 並列数Kは主に『完了までの壁時計時間』に影響し、総インスタンス時間が同じならコストは大きく変わりません。 - 評価ゲート（精度判定）もProcessingとして実行するため、必ず計算コストが発生します。 - Serverless推論は安価ですが、SageMakerの一部機能（例：Model Monitor等）が利用不可のため、監視は自作（Processingで集計）へ寄せる設計が必要です。 参照（公式）： - SageMaker AI Pricing: https://aws.amazon.com/sagemaker/ai/pricing/ - Serverless endpoints: https://docs.aws.amazon.com/sagemaker/latest/dg/serverless-endpoints.html - EventBridge Pricing: https://aws.amazon.com/eventbridge/pricing/
A5: 1) Go to Inputs and adjust blue cells. 2) Instance hourly rates and serverless $/sec are in Pricing; update them for your exact us-east-1 prices. 3) Calc computes monthly costs for patterns A/B/C simultaneously. 4) Summary shows the selected pattern total and a side-by-side comparison. Important modeling notes: - Parallelism (job concurrency) primarily affects wall-clock completion time; cost is driven by total instance-hours. - ECR image load overhead is modeled as extra minutes per Processing/Training job run. - Serverless vs Realtime vs Batch inference can be mixed per event; Realtime and Batch base costs are counted once if used by any event. - Add pattern-specific inference multipliers if per-user model selection increases latency (e.g., Multi-Model Endpoint caching misses). Operational sizing section (Inputs→M) provides approximate wall-clock duration per retrain cycle and required concurrency K.

Sheet 詳細_再学習
A1: 詳細：再学習パイプライン（前処理→学習→評価/ゲート→デプロイ判定）
A3: 項目 | B3: A（個人） | C3: B（グループ） | D3: C（共通） | E3: 単位 | F3: 計算式/参照 | G3: コストが発生する理由
A4: モデル数 M | B4: =入力!B6 | C4: =入力!B9 | D4: =入力!B10 | E4: models | F4: 入力シートの定義 | G4: モデル数に比例して再学習ジョブ数が増えるため
A5: 再学習サイクル回数 R（月あたり） | B5: =入力!B14 | C5: =入力!B14 | D5: =入力!B14 | E5: cycles/month | F5: 入力!B14 | G5: 頻度が高いほど、同じ処理を繰り返すためコストが増える
A6: Processing分（共通：前処理＋評価、ECR含む） | B6: =入力!B22 | C6: =入力!B22 | D6: =入力!B22 | E6: min/cycle | F6: 入力!B22 | G6: Processingはインスタンス時間課金。ECRロード等の固定時間も含まれる
A7: Training分（モデルあたり：学習、ECR含む） | B7: =入力!B23 | C7: =入力!B23 | D7: =入力!B23 | E7: min/model/run | F7: 入力!B23 | G7: Trainingはインスタンス時間課金。学習時間が長いほどコスト増
A8: Processing インスタンス | B8: =入力!B27 | C8: =入力!B27 | D8: =入力!B27 | E8: instance | F8: 入力!B27 | G8: インスタンス単価（USD/時間）がコストに直結
A9: Training インスタンス | B9: =入力!B28 | C9: =入力!B28 | D9: =入力!B28 | E9: instance | F9: 入力!B28 | G9: 同上
A10: Processing 単価（USD/時間） | B10: =VLOOKUP(入力!B27,単価!$A$2:$B$10,2,FALSE) | C10: =VLOOKUP(入力!B27,単価!$A$2:$B$10,2,FALSE) | D10: =VLOOKUP(入力!B27,単価!$A$2:$B$10,2,FALSE) | E10: USD/hour | F10: 単価シート参照
A11: Training 単価（USD/時間） | B11: =VLOOKUP(入力!B28,単価!$A$2:$B$10,2,FALSE) | C11: =VLOOKUP(入力!B28,単価!$A$2:$B$10,2,FALSE) | D11: =VLOOKUP(入力!B28,単価!$A$2:$B$10,2,FALSE) | E11: USD/hour | F11: 単価シート参照
A12: 月額：Processing（共通前処理＋評価） | B12: =B5*(B6/60)*B10 | C12: =C5*(C6/60)*C10 | D12: =D5*(D6/60)*D10 | E12: USD/month | F12: M×R×(proc_min/60)×proc_rate | G12: 前処理・評価の計算資源利用時間に課金
A13: 月額：Training（モデル数に比例） | B13: =B4*B5*(B7/60)*B11 | C13: =C4*C5*(C7/60)*C11 | D13: =D4*D5*(D7/60)*D11 | E13: USD/month | F13: M×R×(train_min/60)×train_rate | G13: 学習ジョブの計算資源利用時間に課金
A14: 月額：再学習合計（Processing+Training） | B14: =B12+B13 | C14: =C12+C13 | D14: =D12+D13 | E14: USD/month | F14: 上記合計 | G14: 再学習パイプラインの月額支配項
A15: 壁時計時間（共通Processing：1サイクル） | B15: =入力!B22/60 | C15: =入力!B22/60 | D15: =入力!B22/60 | E15: hours/cycle | F15: 入力!B85 | G15: 運用（完了時間）設計に影響。コストではなく所要時間の目安
A16: 並列数 K（同時Trainingジョブ数） | B16: =入力!B83 | C16: =入力!B83 | D16: =入力!B83 | E16: jobs | F16: 入力!B83 | G16: 並列数を増やすと完了は早くなるが、総インスタンス時間が同じならコストは概ね不変
A17: 概算壁時計（1サイクル）=Processing + CEILING(M/K)*Training | B17: =B15+CEILING(B4/B16,1)*(入力!B23/60) | C17: =C15+CEILING(C4/C16,1)*(入力!B23/60) | D17: =D15+CEILING(D4/D16,1)*(入力!B23/60) | E17: hours/cycle | F17: CEILING(M/K)*wall_clock_per_model | G17: 運用上の締切（夜間バッチ等）を満たせるかの確認

Sheet 詳細_監視
A1: 詳細：ドリフト監視（データドリフト/モデル品質劣化）
A3: 項目 | B3: A（個人） | C3: B（グループ） | D3: C（共通） | E3: 単位 | F3: 計算式/参照 | G3: コストが発生する理由
A4: 監視単位（PerEndpoint / PerModel） | B4: =入力!B33 | C4: =入力!B33 | D4: =入力!B33 | E4: text | F4: 入力!B33 | G4: 監視対象数（エンティティ）が変わり、費用に影響
A5: 監視対象数（エンティティ） | B5: =IF(入力!B33="PerModel",入力!B6,入力!B34) | C5: =IF(入力!B33="PerModel",入力!B9,入力!B34) | D5: =IF(入力!B33="PerModel",入力!B10,入力!B34) | E5: entities | F5: PerModelならモデル数、PerEndpointならエンドポイント数 | G5: 対象数に比例して監視ジョブが増える（設計次第）
A6: 監視回数（月） | B6: =入力!B35 | C6: =入力!B35 | D6: =入力!B35 | E6: runs/month | F6: 入力!B35 | G6: 頻度に比例してコスト増
A7: 監視分（オーバーヘッド込み） | B7: =入力!B37 | C7: =入力!B37 | D7: =入力!B37 | E7: min/run | F7: 入力!B37 | G7: 監視はProcessing相当の計算ジョブ
A8: 監視インスタンス | B8: =入力!B27 | C8: =入力!B27 | D8: =入力!B27 | E8: instance | F8: 入力!B27 | G8: 単価がコストに直結
A9: 監視単価（USD/時間） | B9: =VLOOKUP(入力!B27,単価!$A$2:$B$10,2,FALSE) | C9: =VLOOKUP(入力!B27,単価!$A$2:$B$10,2,FALSE) | D9: =VLOOKUP(入力!B27,単価!$A$2:$B$10,2,FALSE) | E9: USD/hour | F9: 単価参照
A10: 月額：ドリフト監視 | B10: =B5*B6*(B7/60)*B8 | C10: =C5*C6*(C7/60)*C8 | D10: =D5*D6*(D7/60)*D8 | E10: USD/month | F10: entities×runs×(min/60)×rate | G10: 監視ジョブのインスタンス時間課金

Sheet 詳細_トリガー
A1: 詳細：再学習トリガー（EventBridge）
A3: 項目 | B3: A（個人） | C3: B（グループ） | D3: C（共通） | E3: 単位 | F3: 計算式/参照 | G3: コストが発生する理由
A4: トリガー回数（月） | B4: =入力!B46 | C4: =入力!B46 | D4: =入力!B46 | E4: events/month | F4: 入力!B46 | G4: スケジュール/イベントで再学習起動するたびに課金
A5: EventBridge単価（USD/100万イベント） | B5: =入力!B47 | C5: =入力!B47 | D5: =入力!B47 | E5: USD/1M | F5: 入力!B47
A6: 月額：トリガー（EventBridge） | B6: =B4/1000000*B5 | C6: =C4/1000000*C5 | D6: =D4/1000000*D5 | E6: USD/month | F6: M×events_per_model ÷1e6 × price | G6: 通常は小さいが、Aで頻度が高いと増える

Sheet 詳細_モデル管理
A1: 詳細：モデル成果物の保管（S3）/ レジストリ（メタデータ）
A3: 項目 | B3: A（個人） | C3: B（グループ） | D3: C（共通） | E3: 単位 | F3: 計算式/参照 | G3: コストが発生する理由
A4: モデル成果物サイズ | B4: =入力!B41 | C4: =入力!B41 | D4: =入力!B41 | E4: MB/model/version | F4: 入力!B41 | G4: モデル数×サイズ×保持世代で容量課金が増える
A5: 保持バージョン数 | B5: =入力!B42 | C5: =入力!B42 | D5: =入力!B42 | E5: versions | F5: 入力!B42 | G5: ロールバックや監査要件で保持を増やすとコスト増
A6: S3単価 | B6: =入力!B43 | C6: =入力!B43 | D6: =入力!B43 | E6: USD/GB-month | F6: 入力!B43 | G6: ストレージ容量課金
A7: 月額：モデル保管（S3） | B7: =入力!B6*B4*B5/1024*B6 | C7: =入力!B9*C4*C5/1024*C6 | D7: =入力!B10*D4*D5/1024*D6 | E7: USD/month | F7: M×sizeMB×versions ÷1024 × price | G7: S3容量課金（GB-month）

Sheet 詳細_推論
A1: 詳細：推論コスト（イベント別・方式別）
A3: 項目 | B3: A（個人） | C3: B（グループ） | D3: C（共通） | E3: 単位 | F3: 計算式/参照 | G3: コストが発生する理由
A4: 月間リクエスト（イベント1:初乗車） | B4: =入力!B53 | C4: =入力!B53 | D4: =入力!B53 | E4: req/month | F4: 入力!B53 | G4: ユーザー数×頻度に比例
A5: 月間リクエスト（イベント2:充電前） | B5: =入力!B54 | C5: =入力!B54 | D5: =入力!B54 | E5: req/month | F5: 入力!B54 | G5: 同上
A6: 方式（イベント1） | B6: =入力!B55 | C6: =入力!B55 | D6: =入力!B55 | E6: text | F6: 入力!B55 | G6: 方式により課金モデルが異なる（Serverless/Realtime/Batch）
A7: 方式（イベント2） | B7: =入力!B56 | C7: =入力!B56 | D7: =入力!B56 | E7: text | F7: 入力!B56 | G7: 同上
A8: Serverless 平均実行時間 | B8: =入力!B60 | C8: =入力!B60 | D8: =入力!B60 | E8: ms | F8: 入力!B60 | G8: 実行時間（秒）に従量課金
A9: 推論時間倍率（A/B/C） | B9: =入力!B78 | C9: =入力!B79 | D9: =入力!B80 | E9: x | F9: 入力!B78〜B80 | G9: MME等で遅くなる場合の補正（任意）
A10: Serverless 単価（USD/秒） | B10: =入力!B63 | C10: =入力!B63 | D10: =入力!B63 | E10: USD/sec | F10: 入力!B63
A11: Serverless データ単価（USD/GB） | B11: =入力!B64 | C11: =入力!B64 | D11: =入力!B64 | E11: USD/GB | F11: 入力!B64 | G11: 入出力データ量に従量課金
A12: データサイズ（IN+OUT） | B12: =(入力!B61+入力!B62) | C12: =(入力!B61+入力!B62) | D12: =(入力!B61+入力!B62) | E12: KB/req | F12: 入力!B61,B62
A13: 月額：Serverless（計算） | B13: =((IF(入力!B55="Serverless",入力!B53,0)+IF(入力!B56="Serverless",入力!B54,0))*(入力!B60/1000)*B9*B10) | C13: =((IF(入力!B55="Serverless",入力!B53,0)+IF(入力!B56="Serverless",入力!B54,0))*(入力!B60/1000)*C9*C10) | D13: =((IF(入力!B55="Serverless",入力!B53,0)+IF(入力!B56="Serverless",入力!B54,0))*(入力!B60/1000)*D9*D10) | E13: USD/month | F13: req×sec×mult×price_sec | G13: Serverlessは実行時間課金（リクエスト数と実行時間に比例）
A14: 月額：Serverless（データ） | B14: =((IF(入力!B55="Serverless",入力!B53,0)+IF(入力!B56="Serverless",入力!B54,0))*B11/1024/1024)*B12 | C14: =((IF(入力!B55="Serverless",入力!B53,0)+IF(入力!B56="Serverless",入力!B54,0))*C11/1024/1024)*C12 | D14: =((IF(入力!B55="Serverless",入力!B53,0)+IF(入力!B56="Serverless",入力!B54,0))*D11/1024/1024)*D12 | E14: USD/month | F14: req×KB→GB×price_GB | G14: 入出力データ量課金
A15: リアルタイム稼働台数 N | B15: =入力!B67 | C15: =入力!B67 | D15: =入力!B67 | E15: instances | F15: 入力!B67 | G15: 冗長化やSLO要件で台数が増える
A16: 月稼働時間 | B16: =入力!B68 | C16: =入力!B68 | D16: =入力!B68 | E16: hours | F16: 入力!B68 | G16: 常時起動の固定費
A17: リアルタイム単価（USD/時間） | B17: =入力!B69 | C17: =入力!B69 | D17: =入力!B69 | E17: USD/hour | F17: 入力!B69
A18: 月額：リアルタイム（固定費） | B18: =IF(OR(入力!B55="Realtime",入力!B56="Realtime"),入力!B67*入力!B68*入力!B69,0) | C18: =IF(OR(入力!B55="Realtime",入力!B56="Realtime"),入力!B67*入力!B68*入力!B69,0) | D18: =IF(OR(入力!B55="Realtime",入力!B56="Realtime"),入力!B67*入力!B68*入力!B69,0) | E18: USD/month | F18: N×730×rate（選択時のみ） | G18: Realtimeは常時起動のためリクエスト数が少なくても課金
A19: バッチ実行回数（月） | B19: =入力!B73 | C19: =入力!B73 | D19: =入力!B73 | E19: runs/month | F19: 入力!B73 | G19: まとめて推論する回数
A20: バッチ実行時間（1回） | B20: =入力!B74 | C20: =入力!B74 | D20: =入力!B74 | E20: hours/run | F20: 入力!B74
A21: バッチ単価（USD/時間） | B21: =入力!B75 | C21: =入力!B75 | D21: =入力!B75 | E21: USD/hour | F21: 入力!B75
A22: 月額：バッチ（固定費） | B22: =IF(OR(入力!B55="Batch",入力!B56="Batch"),入力!B73*入力!B74*入力!B75,0) | C22: =IF(OR(入力!B55="Batch",入力!B56="Batch"),入力!B73*入力!B74*入力!B75,0) | D22: =IF(OR(入力!B55="Batch",入力!B56="Batch"),入力!B73*入力!B74*入力!B75,0) | E22: USD/month | F22: runs×hours×rate（選択時のみ） | G22: Batchはジョブ実行中のみ課金。常時エンドポイント不要
A23: 月額：推論合計（Serverless + Realtime + Batch） | B23: =B13+B14+B18+B22 | C23: =C13+C14+C18+C22 | D23: =D13+D14+D18+D22 | E23: USD/month | F23: 上記合計 | G23: 推論方式の組合せにより総額が変わる
